<?xml version="1.0" ?>
<!-- =================================================================================== -->
<!-- |    This document was autogenerated by xacro from /home/buivn/bui_ws/src/pcd_filter/worm_robot_description/urdf/worm_robot_detail.xacro | -->
<!-- |    EDITING THIS FILE BY HAND IS NOT RECOMMENDED                                 | -->
<!-- =================================================================================== -->
<!-- =================================================================================== -->
<!-- |    This document was autogenerated by xacro from /home/buivn/bui_ws/src/pcd_filter/worm_robot_description/urdf/worm_robot_detail1.xacro | -->
<!-- |    EDITING THIS FILE BY HAND IS NOT RECOMMENDED                                 | -->
<!-- =================================================================================== -->
<robot name="wormRobot" xmlns:xacro="http://www.ros.org/wiki/xacro">
    <!-- <xacro:include filename="$(find pcd_filter)/worm_robot_description/urdf/wr_links_joints.xacro"/> -->
    <link name="base_link">
        <visual>
            <origin rpy="0 0 0" xyz="0 0 0.056" />
            <geometry>
                <box size="0.19 0.21 0.112" />
            </geometry>
        </visual>
    </link>

    <joint name="base_link__link_01" type="revolute">
        <axis xyz="0 1 0" />
        <origin rpy="0.0 0.4084 0.0" xyz="0.0 0.0 0.163" />
        <limit effort="1000.0" lower="-1.4584" upper="0.6416" velocity="0.5" /> <!--the upper and lower are compared to the origin rpy-->
        <!-- <origin rpy="0 0 0" xyz="0 0 0.163" /> -->
        <parent link="base_link" />
        <child link="link_01" />
    </joint>

    <link name="link_01">
        <visual>
            <origin rpy="0 0 0" xyz="0 0 0" />
            <geometry>
                <!-- <cylinder radius="0.35" length="0.4" /> -->
                <box size="0.054 0.1375 0.054" />
            </geometry>
        </visual>
    </link>
    
    <joint name="link_01__link_02" type="revolute">
        <axis xyz="0 0 1" />
        <limit effort="1000.0" lower="-2.8" upper="2.8" velocity="0.5" />
        <origin rpy="0 0 0" xyz="0 0 0.089" />
        <parent link="link_01" />
        <child link="link_02" />
    </joint>
    
    <link name="link_02">
        <visual>
            <origin rpy="0 0 0" xyz="0 0 0" />
            <geometry>
                <!-- <cylinder radius="0.35" length="0.4" /> -->
                <box size="0.05 0.05 0.099" />
            </geometry>
        </visual>
    </link>
    
    <joint name="link_02__link_03" type="revolute">
        <axis xyz="0 1 0" />
        <!-- <limit effort="1000.0" lower="-1.5" upper="-0.05" velocity="0.5" /> -->
        <limit effort="1000.0" lower="-1.1858407346" upper="0.2641592654" velocity="0.5" />
        <origin rpy="0 -0.314593 0" xyz="0 0 0.085" />
        <!-- <origin rpy="0 0 0" xyz="0 0 0.085" /> -->
        <parent link="link_02" />
        <child link="link_03" />
    </joint>
    
    <link name="link_03">
        <visual>
            <origin rpy="0 0 0" xyz="0 0 0" />
            <geometry>
                <!-- <cylinder radius="0.35" length="0.4" /> -->
                <box size="0.045 0.1175 0.045" />
            </geometry>
        </visual>
    </link>
    
    <joint name="link_03__link_04" type="revolute">
        <axis xyz="0 1 0" />
        <!-- <limit effort="1000.0" lower="-1.5" upper="-0.03" velocity="0.5" /> -->
        <limit effort="1000.0" lower="-0.620354" upper="0.849646" velocity="0.5" />
        <origin rpy="0 -0.879646 0" xyz="0 0 0.15212" />
        <!-- <origin rpy="0 0 0" xyz="0 0 0.15212" /> -->
        <parent link="link_03" />
        <child link="link_04" />
    </joint>
    <link name="link_04">
        <visual>
            <origin rpy="0 0 0" xyz="0 0 0" />
            <geometry>
                <!-- <cylinder radius="0.35" length="0.4" /> -->
                <box size="0.045 0.1175 0.045" />
            </geometry>
        </visual>
    </link>
    <joint name="link_04__link_05" type="revolute">
        <axis xyz="0 0 1" />
        <limit effort="1000.0" lower="-2.8" upper="2.8" velocity="0.5" />
        <origin rpy="0 0 0" xyz="0 0 0.085" />
        <parent link="link_04" />
        <child link="link_05" />
    </joint>
    <link name="link_05">
        <visual>
            <origin rpy="0 0 0" xyz="0 0 0" />
            <geometry>
                <!-- <cylinder radius="0.35" length="0.4" /> -->
                <box size="0.05 0.05 0.099" />
            </geometry>
        </visual>
    </link>
    <joint name="link_05__link_06" type="revolute">
        <axis xyz="0 1 0" />
        <limit effort="1000.0" lower="-1.05" upper="1.05" velocity="0.5" />
        <origin rpy="0 0 0" xyz="0 0 0.089" />
        <parent link="link_05" />
        <child link="link_06" />
    </joint>
    <link name="link_06">
        <visual>
            <origin rpy="0 0 0" xyz="0 0 0" />
            <geometry>
                <!-- <cylinder radius="0.35" length="0.4" /> -->
                <box size="0.054 0.1375 0.054" />
            </geometry>
        </visual>
    </link>
    <joint name="link_06__end_effector" type="fixed">
        <!-- <axis xyz="0 1 0"/> -->
        <!-- <limit effort="1000.0" lower="-1.4" upper="1.4" velocity="0.5"/> -->
        <origin rpy="0 0 0" xyz="0 0 0.163" />
        <parent link="link_06" />
        <child link="end_effector" />
    </joint>
    <link name="end_effector">
        <visual>
            <origin rpy="0 0 0" xyz="0 0 -0.056" />
            <geometry>
                <!-- <cylinder radius="0.35" length="0.4" /> -->
                <box size="0.19 0.21 0.112" />
            </geometry>
        </visual>
    </link>
    
<transmission name="trans_base_link__link_01">
        <type>transmission_interface/SimpleTransmission</type>
        <joint name="base_link__link_01">
            <hardwareInterface>hardware_interface/EffortJointInterface</hardwareInterface>
        </joint>
        <actuator name="base_link__link_01_motor">
            <hardwareInterface>hardware_interface/EffortJointInterface</hardwareInterface>
            <mechanicalReduction>1</mechanicalReduction>
        </actuator>
    </transmission>
    <transmission name="trans_link_01__link_02">
        <type>transmission_interface/SimpleTransmission</type>
        <joint name="link_01__link_02">
            <hardwareInterface>hardware_interface/EffortJointInterface</hardwareInterface>
        </joint>
        <actuator name="link_01__link_02_motor">
            <hardwareInterface>hardware_interface/EffortJointInterface</hardwareInterface>
            <mechanicalReduction>1</mechanicalReduction>
        </actuator>
    </transmission>
    <transmission name="trans_link_02__link_03">
        <type>transmission_interface/SimpleTransmission</type>
        <joint name="link_02__link_03">
            <hardwareInterface>hardware_interface/EffortJointInterface</hardwareInterface>
        </joint>
        <actuator name="link_02__link_03_motor">
            <hardwareInterface>hardware_interface/EffortJointInterface</hardwareInterface>
            <mechanicalReduction>1</mechanicalReduction>
        </actuator>
    </transmission>
    <transmission name="trans_link_03__link_04">
        <type>transmission_interface/SimpleTransmission</type>
        <joint name="link_03__link_04">
            <hardwareInterface>hardware_interface/EffortJointInterface</hardwareInterface>
        </joint>
        <actuator name="link_03__link_04_motor">
            <hardwareInterface>hardware_interface/EffortJointInterface</hardwareInterface>
            <mechanicalReduction>1</mechanicalReduction>
        </actuator>
    </transmission>
    <transmission name="trans_link_04__link_05">
        <type>transmission_interface/SimpleTransmission</type>
        <joint name="link_04__link_05">
            <hardwareInterface>hardware_interface/EffortJointInterface</hardwareInterface>
        </joint>
        <actuator name="link_04__link_05_motor">
            <hardwareInterface>hardware_interface/EffortJointInterface</hardwareInterface>
            <mechanicalReduction>1</mechanicalReduction>
        </actuator>
    </transmission>
    <transmission name="trans_link_05__link_06">
        <type>transmission_interface/SimpleTransmission</type>
        <joint name="link_05__link_06">
            <hardwareInterface>hardware_interface/EffortJointInterface</hardwareInterface>
        </joint>
        <actuator name="link_05__link_06_motor">
            <hardwareInterface>hardware_interface/EffortJointInterface</hardwareInterface>
            <mechanicalReduction>1</mechanicalReduction>
        </actuator>
    </transmission>
    <gazebo>
        <plugin filename="libgazebo_ros_control.so" name="gazebo_ros_control">
            <robotNamespace>/</robotNamespace>
        </plugin>
    </gazebo>
    <transmission name="trans_base_link__link_01">
        <type>transmission_interface/SimpleTransmission</type>
        <joint name="base_link__link_01">
            <hardwareInterface>hardware_interface/EffortJointInterface</hardwareInterface>
        </joint>
        <actuator name="base_link__link_01_motor">
            <hardwareInterface>hardware_interface/EffortJointInterface</hardwareInterface>
            <mechanicalReduction>1</mechanicalReduction>
        </actuator>
    </transmission>
    <transmission name="trans_link_01__link_02">
        <type>transmission_interface/SimpleTransmission</type>
        <joint name="link_01__link_02">
            <hardwareInterface>hardware_interface/EffortJointInterface</hardwareInterface>
        </joint>
        <actuator name="link_01__link_02_motor">
            <hardwareInterface>hardware_interface/EffortJointInterface</hardwareInterface>
            <mechanicalReduction>1</mechanicalReduction>
        </actuator>
    </transmission>
    <transmission name="trans_link_02__link_03">
        <type>transmission_interface/SimpleTransmission</type>
        <joint name="link_02__link_03">
            <hardwareInterface>hardware_interface/EffortJointInterface</hardwareInterface>
        </joint>
        <actuator name="link_02__link_03_motor">
            <hardwareInterface>hardware_interface/EffortJointInterface</hardwareInterface>
            <mechanicalReduction>1</mechanicalReduction>
        </actuator>
    </transmission>
    <transmission name="trans_link_03__link_04">
        <type>transmission_interface/SimpleTransmission</type>
        <joint name="link_03__link_04">
            <hardwareInterface>hardware_interface/EffortJointInterface</hardwareInterface>
        </joint>
        <actuator name="link_03__link_04_motor">
            <hardwareInterface>hardware_interface/EffortJointInterface</hardwareInterface>
            <mechanicalReduction>1</mechanicalReduction>
        </actuator>
    </transmission>
    <transmission name="trans_link_04__link_05">
        <type>transmission_interface/SimpleTransmission</type>
        <joint name="link_04__link_05">
            <hardwareInterface>hardware_interface/EffortJointInterface</hardwareInterface>
        </joint>
        <actuator name="link_04__link_05_motor">
            <hardwareInterface>hardware_interface/EffortJointInterface</hardwareInterface>
            <mechanicalReduction>1</mechanicalReduction>
        </actuator>
    </transmission>
    <transmission name="trans_link_05__link_06">
        <type>transmission_interface/SimpleTransmission</type>
        <joint name="link_05__link_06">
            <hardwareInterface>hardware_interface/EffortJointInterface</hardwareInterface>
        </joint>
        <actuator name="link_05__link_06_motor">
            <hardwareInterface>hardware_interface/EffortJointInterface</hardwareInterface>
            <mechanicalReduction>1</mechanicalReduction>
        </actuator>
    </transmission>
    <gazebo>
        <plugin name="gazebo_ros_control" filename="libgazebo_ros_control.so">
            <robotNamespace>/</robotNamespace>
        </plugin>
    </gazebo>
</robot>